Workbook

Sheet Synthèse
A1: Façadiers français de 6 à 199 salariés : vérification et dispersion NAF
A2: Données au 24/09/2026, mises à jour le 26/09/2026. Sources : API Recherche d'entreprises (État), INSEE, ADEME (RGE), BODACC, recherche web.
A4: Message clé
A5: • Aucun code NAF ne suffit à cibler les façadiers : le premier (43.99C, maçonnerie) n'en couvre que 34 %, il faut 8 codes pour atteindre 90 %, et ces codes regroupent aussi des maçons, peintres et isolateurs qui ne font pas de façade (dans un test sur 100 entreprises tirées au hasard en 43.99C, seules 26 ont une activité façade, dont 5 en cœur de métier).
A6: • Le nom est un bon filtre, mais il ne suffit pas : 77 à 86 % des entreprises vérifiées dont le nom contient « façade » sont bien des façadiers ; les autres sont menuisiers, étancheurs, échafaudagistes ou plâtriers (en BTP, la « 5e façade » désigne la toiture). Surtout, il rate les façadiers sans ce mot dans leur nom.
A7: • Un ciblage fiable croise plusieurs signaux : qualification RGE « isolation des murs par l'extérieur », site web, activité déclarée au greffe, contrôle web.
A8: • Le statut « actif » du répertoire ne suffit pas : une partie des façadiers confirmés est en liquidation ou en redressement judiciaire d'après le BODACC.
A10: Chiffres clés
A11: Indicateur | B11: Valeur | C11: Précision
A12: Entreprises extraites (actives, 6 à 199 salariés, mot-clé façade / ravalement / bardage) | B12: 629 | C12: Saisi : résultat de l'extraction API du 24/09/2026 (393 + 161 + 89 résultats, doublons retirés).
A13: Exclues par la liste de mots d'exclusion (nettoyage, conseil…) | B13: 4 | C13: Saisi : filtre de l'extraction.
A14: Entreprises analysées | B14: =COUNTA(Base!$A$2:$A$626) -> 625 | C14: Toutes les lignes de l'onglet Base.
A15: Façadiers confirmés | B15: =COUNTIF(Base!$C$2:$C$626,"Confirmé") -> 498 | C15: Preuve d'une activité façade (voir Méthodologie).
A16: dont prospectables (sans alerte juridique) | B16: =COUNTIFS(Base!$C$2:$C$626,"Confirmé",Base!$E$2:$E$626,"") -> 465 | C16: Liste dans l'onglet Prospects.
A17: dont en liquidation ou plan de cession | B17: =COUNTIFS(Base!$C$2:$C$626,"Confirmé",Base!$E$2:$E$626,"NE PAS PROSPECTER*") -> 26 | C17: Source BODACC.
A18: dont en redressement ou sauvegarde récents | B18: =COUNTIFS(Base!$C$2:$C$626,"Confirmé",Base!$E$2:$E$626,"Vigilance*") -> 5 | C18: Procédure ouverte en 2025-2026, vérifiée au BODACC le 26/09/2026.
A19: dont radiés au BODACC | B19: =COUNTIFS(Base!$C$2:$C$626,"Confirmé",Base!$E$2:$E$626,"Radiée*") -> 2
A20: Probables (indices sans preuve directe) | B20: =COUNTIF(Base!$C$2:$C$626,"Probable") -> 64 | C20: Surtout des entreprises « bardage » et « ravalement » restées non vérifiées : quota de 200 recherches web de l'outil d'IA atteint (voir Limites 3).
A21: Douteux (indices d'un autre métier) | B21: =COUNTIF(Base!$C$2:$C$626,"Douteux") -> 26
A22: Hors cible | B22: =COUNTIF(Base!$C$2:$C$626,"Hors cible*") -> 37 | C22: Autre métier, fabricant, bureau d'études, collectivité, commerce…
A23: Codes NAF distincts parmi les façadiers confirmés | B23: ='Dispersion NAF'!$B$4 -> 23 | C23: Voir onglet Dispersion NAF.
A24: Part du 1er code NAF (43.99C) parmi les confirmés | B24: ='Dispersion NAF'!$D$7 -> 0.33534137
A25: Part cumulée des 8 premiers codes NAF (tous en division 43) | B25: ='Dispersion NAF'!$E$14 -> 0.89759036
A26: Taux de confirmation parmi les entreprises vérifiées | B26: =B15/(B14-COUNTIF(Base!$F$2:$F$626,"non vérifié*")) -> 0.8615917 | C26: Confirmés / (analysées − non vérifiées). Par méthode : RGE 100 % (le label vaut preuve), recherche web 77 %, BODACC 81 %.
A28: Façadiers confirmés par spécialité
A29: Spécialité | B29: Nombre | C29: Lecture
A30: Façadier (ravalement, enduits, ITE, bardage) | B30: =COUNTIFS(Base!$C$2:$C$626,"Confirmé",Base!$D$2:$D$626,A30) -> 438 | C30: Catégorie par défaut (confirmés non rangés ailleurs). La spécialité est déduite automatiquement du nom, du NAF et de la preuve : elle est indicative.
A31: Couvreur / étancheur faisant du bardage | B31: =COUNTIFS(Base!$C$2:$C$626,"Confirmé",Base!$D$2:$D$626,A31) -> 43 | C31: Inclus mais à distinguer : le bardage est une activité secondaire de couvreurs.
A32: Façade légère / métallique (murs-rideaux, vêture) | B32: =COUNTIFS(Base!$C$2:$C$626,"Confirmé",Base!$D$2:$D$626,A32) -> 7 | C32: Inclus : métier de l'enveloppe, chantiers et clientèle différents.
A33: Multi-activité (façade parmi d'autres métiers) | B33: =COUNTIFS(Base!$C$2:$C$626,"Confirmé",Base!$D$2:$D$626,A33) -> 10 | C33: Entreprises générales ou peintres faisant aussi de la façade.
A34: Total | B34: =SUM(B30:B33) -> 498 | C34: Égal au nombre de façadiers confirmés.
A36: Périmètre : entreprises actives en France (métropole et DOM), 6 à 199 salariés selon la tranche INSEE, trouvées par la recherche de l'API sur façade, ravalement ou bardage (nom, enseigne ou autres champs : 43 n'ont pas le mot-clé dans leur nom actuel). Lire l'onglet Limites avant toute utilisation des chiffres.

Sheet Dispersion NAF
A1: Dispersion des façadiers confirmés par code NAF
A2: Chaque ligne compte les entreprises classées « Confirmé » dans l'onglet Base (formules).
A4: Codes NAF distincts | B4: =COUNTIF(C7:C29,">0") -> 23
A6: Code NAF | B6: Libellé NAF | C6: Façadiers confirmés | D6: Part | E6: Part cumulée | F6: Cœur de métier | G6: Couvreurs-bardeurs | H6: Façade légère | I6: Multi-activité
A7: 43.99C | B7: Travaux de maçonnerie générale et gros œuvre de bâtiment | C7: =COUNTIFS(Base!$I$2:$I$626,A7,Base!$C$2:$C$626,"Confirmé") -> 167 | D7: =C7/$C$30 -> 0.33534137 | E7: =D7 -> 0.33534137 | F7: =COUNTIFS(Base!$I$2:$I$626,$A7,Base!$C$2:$C$626,"Confirmé",Base!$D$2:$D$626,"Façadier (ravalement, enduits, ITE, bardage)") -> 165 | G7: =COUNTIFS(Base!$I$2:$I$626,$A7,Base!$C$2:$C$626,"Confirmé",Base!$D$2:$D$626,"Couvreur / étancheur faisant du bardage") -> 0 | H7: =COUNTIFS(Base!$I$2:$I$626,$A7,Base!$C$2:$C$626,"Confirmé",Base!$D$2:$D$626,"Façade légère / métallique (murs-rideaux, vêture)") -> 0 | I7: =COUNTIFS(Base!$I$2:$I$626,$A7,Base!$C$2:$C$626,"Confirmé",Base!$D$2:$D$626,"Multi-activité (façade parmi d'autres métiers)") -> 2
A8: 43.34Z | B8: Travaux de peinture et vitrerie | C8: =COUNTIFS(Base!$I$2:$I$626,A8,Base!$C$2:$C$626,"Confirmé") -> 88 | D8: =C8/$C$30 -> 0.17670683 | E8: =E7+D8 -> 0.51204819 | F8: =COUNTIFS(Base!$I$2:$I$626,$A8,Base!$C$2:$C$626,"Confirmé",Base!$D$2:$D$626,"Façadier (ravalement, enduits, ITE, bardage)") -> 86 | G8: =COUNTIFS(Base!$I$2:$I$626,$A8,Base!$C$2:$C$626,"Confirmé",Base!$D$2:$D$626,"Couvreur / étancheur faisant du bardage") -> 0 | H8: =COUNTIFS(Base!$I$2:$I$626,$A8,Base!$C$2:$C$626,"Confirmé",Base!$D$2:$D$626,"Façade légère / métallique (murs-rideaux, vêture)") -> 0 | I8: =COUNTIFS(Base!$I$2:$I$626,$A8,Base!$C$2:$C$626,"Confirmé",Base!$D$2:$D$626,"Multi-activité (façade parmi d'autres métiers)") -> 2
A9: 43.29A | B9: Travaux d'isolation | C9: =COUNTIFS(Base!$I$2:$I$626,A9,Base!$C$2:$C$626,"Confirmé") -> 43 | D9: =C9/$C$30 -> 0.086345382 | E9: =E8+D9 -> 0.59839357 | F9: =COUNTIFS(Base!$I$2:$I$626,$A9,Base!$C$2:$C$626,"Confirmé",Base!$D$2:$D$626,"Façadier (ravalement, enduits, ITE, bardage)") -> 43 | G9: =COUNTIFS(Base!$I$2:$I$626,$A9,Base!$C$2:$C$626,"Confirmé",Base!$D$2:$D$626,"Couvreur / étancheur faisant du bardage") -> 0 | H9: =COUNTIFS(Base!$I$2:$I$626,$A9,Base!$C$2:$C$626,"Confirmé",Base!$D$2:$D$626,"Façade légère / métallique (murs-rideaux, vêture)") -> 0 | I9: =COUNTIFS(Base!$I$2:$I$626,$A9,Base!$C$2:$C$626,"Confirmé",Base!$D$2:$D$626,"Multi-activité (façade parmi d'autres métiers)") -> 0
A10: 43.39Z | B10: Autres travaux de finition | C10: =COUNTIFS(Base!$I$2:$I$626,A10,Base!$C$2:$C$626,"Confirmé") -> 41 | D10: =C10/$C$30 -> 0.082329317 | E10: =E9+D10 -> 0.68072289 | F10: =COUNTIFS(Base!$I$2:$I$626,$A10,Base!$C$2:$C$626,"Confirmé",Base!$D$2:$D$626,"Façadier (ravalement, enduits, ITE, bardage)") -> 40 | G10: =COUNTIFS(Base!$I$2:$I$626,$A10,Base!$C$2:$C$626,"Confirmé",Base!$D$2:$D$626,"Couvreur / étancheur faisant du bardage") -> 0 | H10: =COUNTIFS(Base!$I$2:$I$626,$A10,Base!$C$2:$C$626,"Confirmé",Base!$D$2:$D$626,"Façade légère / métallique (murs-rideaux, vêture)") -> 0 | I10: =COUNTIFS(Base!$I$2:$I$626,$A10,Base!$C$2:$C$626,"Confirmé",Base!$D$2:$D$626,"Multi-activité (façade parmi d'autres métiers)") -> 1
A11: 43.99D | B11: Autres travaux spécialisés de construction | C11: =COUNTIFS(Base!$I$2:$I$626,A11,Base!$C$2:$C$626,"Confirmé") -> 33 | D11: =C11/$C$30 -> 0.06626506 | E11: =E10+D11 -> 0.74698795 | F11: =COUNTIFS(Base!$I$2:$I$626,$A11,Base!$C$2:$C$626,"Confirmé",Base!$D$2:$D$626,"Façadier (ravalement, enduits, ITE, bardage)") -> 33 | G11: =COUNTIFS(Base!$I$2:$I$626,$A11,Base!$C$2:$C$626,"Confirmé",Base!$D$2:$D$626,"Couvreur / étancheur faisant du bardage") -> 0 | H11: =COUNTIFS(Base!$I$2:$I$626,$A11,Base!$C$2:$C$626,"Confirmé",Base!$D$2:$D$626,"Façade légère / métallique (murs-rideaux, vêture)") -> 0 | I11: =COUNTIFS(Base!$I$2:$I$626,$A11,Base!$C$2:$C$626,"Confirmé",Base!$D$2:$D$626,"Multi-activité (façade parmi d'autres métiers)") -> 0
A12: 43.99A | B12: Travaux d'étanchéification | C12: =COUNTIFS(Base!$I$2:$I$626,A12,Base!$C$2:$C$626,"Confirmé") -> 30 | D12: =C12/$C$30 -> 0.060240964 | E12: =E11+D12 -> 0.80722892 | F12: =COUNTIFS(Base!$I$2:$I$626,$A12,Base!$C$2:$C$626,"Confirmé",Base!$D$2:$D$626,"Façadier (ravalement, enduits, ITE, bardage)") -> 12 | G12: =COUNTIFS(Base!$I$2:$I$626,$A12,Base!$C$2:$C$626,"Confirmé",Base!$D$2:$D$626,"Couvreur / étancheur faisant du bardage") -> 18 | H12: =COUNTIFS(Base!$I$2:$I$626,$A12,Base!$C$2:$C$626,"Confirmé",Base!$D$2:$D$626,"Façade légère / métallique (murs-rideaux, vêture)") -> 0 | I12: =COUNTIFS(Base!$I$2:$I$626,$A12,Base!$C$2:$C$626,"Confirmé",Base!$D$2:$D$626,"Multi-activité (façade parmi d'autres métiers)") -> 0
A13: 43.91B | B13: Travaux de couverture par éléments | C13: =COUNTIFS(Base!$I$2:$I$626,A13,Base!$C$2:$C$626,"Confirmé") -> 30 | D13: =C13/$C$30 -> 0.060240964 | E13: =E12+D13 -> 0.86746988 | F13: =COUNTIFS(Base!$I$2:$I$626,$A13,Base!$C$2:$C$626,"Confirmé",Base!$D$2:$D$626,"Façadier (ravalement, enduits, ITE, bardage)") -> 6 | G13: =COUNTIFS(Base!$I$2:$I$626,$A13,Base!$C$2:$C$626,"Confirmé",Base!$D$2:$D$626,"Couvreur / étancheur faisant du bardage") -> 22 | H13: =COUNTIFS(Base!$I$2:$I$626,$A13,Base!$C$2:$C$626,"Confirmé",Base!$D$2:$D$626,"Façade légère / métallique (murs-rideaux, vêture)") -> 0 | I13: =COUNTIFS(Base!$I$2:$I$626,$A13,Base!$C$2:$C$626,"Confirmé",Base!$D$2:$D$626,"Multi-activité (façade parmi d'autres métiers)") -> 2
A14: 43.31Z | B14: Travaux de plâtrerie | C14: =COUNTIFS(Base!$I$2:$I$626,A14,Base!$C$2:$C$626,"Confirmé") -> 15 | D14: =C14/$C$30 -> 0.030120482 | E14: =E13+D14 -> 0.89759036 | F14: =COUNTIFS(Base!$I$2:$I$626,$A14,Base!$C$2:$C$626,"Confirmé",Base!$D$2:$D$626,"Façadier (ravalement, enduits, ITE, bardage)") -> 15 | G14: =COUNTIFS(Base!$I$2:$I$626,$A14,Base!$C$2:$C$626,"Confirmé",Base!$D$2:$D$626,"Couvreur / étancheur faisant du bardage") -> 0 | H14: =COUNTIFS(Base!$I$2:$I$626,$A14,Base!$C$2:$C$626,"Confirmé",Base!$D$2:$D$626,"Façade légère / métallique (murs-rideaux, vêture)") -> 0 | I14: =COUNTIFS(Base!$I$2:$I$626,$A14,Base!$C$2:$C$626,"Confirmé",Base!$D$2:$D$626,"Multi-activité (façade parmi d'autres métiers)") -> 0
A15: 43.33Z | B15: Travaux de revêtement des sols et des murs | C15: =COUNTIFS(Base!$I$2:$I$626,A15,Base!$C$2:$C$626,"Confirmé") -> 14 | D15: =C15/$C$30 -> 0.02811245 | E15: =E14+D15 -> 0.92570281 | F15: =COUNTIFS(Base!$I$2:$I$626,$A15,Base!$C$2:$C$626,"Confirmé",Base!$D$2:$D$626,"Façadier (ravalement, enduits, ITE, bardage)") -> 14 | G15: =COUNTIFS(Base!$I$2:$I$626,$A15,Base!$C$2:$C$626,"Confirmé",Base!$D$2:$D$626,"Couvreur / étancheur faisant du bardage") -> 0 | H15: =COUNTIFS(Base!$I$2:$I$626,$A15,Base!$C$2:$C$626,"Confirmé",Base!$D$2:$D$626,"Façade légère / métallique (murs-rideaux, vêture)") -> 0 | I15: =COUNTIFS(Base!$I$2:$I$626,$A15,Base!$C$2:$C$626,"Confirmé",Base!$D$2:$D$626,"Multi-activité (façade parmi d'autres métiers)") -> 0
A16: 43.32A | B16: Travaux de menuiserie bois et PVC | C16: =COUNTIFS(Base!$I$2:$I$626,A16,Base!$C$2:$C$626,"Confirmé") -> 8 | D16: =C16/$C$30 -> 0.016064257 | E16: =E15+D16 -> 0.94176707 | F16: =COUNTIFS(Base!$I$2:$I$626,$A16,Base!$C$2:$C$626,"Confirmé",Base!$D$2:$D$626,"Façadier (ravalement, enduits, ITE, bardage)") -> 5 | G16: =COUNTIFS(Base!$I$2:$I$626,$A16,Base!$C$2:$C$626,"Confirmé",Base!$D$2:$D$626,"Couvreur / étancheur faisant du bardage") -> 0 | H16: =COUNTIFS(Base!$I$2:$I$626,$A16,Base!$C$2:$C$626,"Confirmé",Base!$D$2:$D$626,"Façade légère / métallique (murs-rideaux, vêture)") -> 3 | I16: =COUNTIFS(Base!$I$2:$I$626,$A16,Base!$C$2:$C$626,"Confirmé",Base!$D$2:$D$626,"Multi-activité (façade parmi d'autres métiers)") -> 0
A17: 41.20A | B17: Construction de maisons individuelles | C17: =COUNTIFS(Base!$I$2:$I$626,A17,Base!$C$2:$C$626,"Confirmé") -> 6 | D17: =C17/$C$30 -> 0.012048193 | E17: =E16+D17 -> 0.95381526 | F17: =COUNTIFS(Base!$I$2:$I$626,$A17,Base!$C$2:$C$626,"Confirmé",Base!$D$2:$D$626,"Façadier (ravalement, enduits, ITE, bardage)") -> 6 | G17: =COUNTIFS(Base!$I$2:$I$626,$A17,Base!$C$2:$C$626,"Confirmé",Base!$D$2:$D$626,"Couvreur / étancheur faisant du bardage") -> 0 | H17: =COUNTIFS(Base!$I$2:$I$626,$A17,Base!$C$2:$C$626,"Confirmé",Base!$D$2:$D$626,"Façade légère / métallique (murs-rideaux, vêture)") -> 0 | I17: =COUNTIFS(Base!$I$2:$I$626,$A17,Base!$C$2:$C$626,"Confirmé",Base!$D$2:$D$626,"Multi-activité (façade parmi d'autres métiers)") -> 0
A18: 41.20B | B18: Construction d'autres bâtiments | C18: =COUNTIFS(Base!$I$2:$I$626,A18,Base!$C$2:$C$626,"Confirmé") -> 4 | D18: =C18/$C$30 -> 0.0080321285 | E18: =E17+D18 -> 0.96184739 | F18: =COUNTIFS(Base!$I$2:$I$626,$A18,Base!$C$2:$C$626,"Confirmé",Base!$D$2:$D$626,"Façadier (ravalement, enduits, ITE, bardage)") -> 3 | G18: =COUNTIFS(Base!$I$2:$I$626,$A18,Base!$C$2:$C$626,"Confirmé",Base!$D$2:$D$626,"Couvreur / étancheur faisant du bardage") -> 0 | H18: =COUNTIFS(Base!$I$2:$I$626,$A18,Base!$C$2:$C$626,"Confirmé",Base!$D$2:$D$626,"Façade légère / métallique (murs-rideaux, vêture)") -> 0 | I18: =COUNTIFS(Base!$I$2:$I$626,$A18,Base!$C$2:$C$626,"Confirmé",Base!$D$2:$D$626,"Multi-activité (façade parmi d'autres métiers)") -> 1
A19: 41.10B | B19: Promotion immobilière de bureaux | C19: =COUNTIFS(Base!$I$2:$I$626,A19,Base!$C$2:$C$626,"Confirmé") -> 3 | D19: =C19/$C$30 -> 0.0060240964 | E19: =E18+D19 -> 0.96787149 | F19: =COUNTIFS(Base!$I$2:$I$626,$A19,Base!$C$2:$C$626,"Confirmé",Base!$D$2:$D$626,"Façadier (ravalement, enduits, ITE, bardage)") -> 3 | G19: =COUNTIFS(Base!$I$2:$I$626,$A19,Base!$C$2:$C$626,"Confirmé",Base!$D$2:$D$626,"Couvreur / étancheur faisant du bardage") -> 0 | H19: =COUNTIFS(Base!$I$2:$I$626,$A19,Base!$C$2:$C$626,"Confirmé",Base!$D$2:$D$626,"Façade légère / métallique (murs-rideaux, vêture)") -> 0 | I19: =COUNTIFS(Base!$I$2:$I$626,$A19,Base!$C$2:$C$626,"Confirmé",Base!$D$2:$D$626,"Multi-activité (façade parmi d'autres métiers)") -> 0
... A29: 43.22A | B29: Travaux d'installation d'eau et de gaz en tous locaux | C29: =COUNTIFS(Base!$I$2:$I$626,A29,Base!$C$2:$C$626,"Confirmé") -> 1 | D29: =C29/$C$30 -> 0.0020080321 | E29: =E28+D29 -> 1 | F29: =COUNTIFS(Base!$I$2:$I$626,$A29,Base!$C$2:$C$626,"Confirmé",Base!$D$2:$D$626,"Façadier (ravalement, enduits, ITE, bardage)") -> 0 | G29: =COUNTIFS(Base!$I$2:$I$626,$A29,Base!$C$2:$C$626,"Confirmé",Base!$D$2:$D$626,"Couvreur / étancheur faisant du bardage") -> 1 | H29: =COUNTIFS(Base!$I$2:$I$626,$A29,Base!$C$2:$C$626,"Confirmé",Base!$D$2:$D$626,"Façade légère / métallique (murs-rideaux, vêture)") -> 0 | I29: =COUNTIFS(Base!$I$2:$I$626,$A29,Base!$C$2:$C$626,"Confirmé",Base!$D$2:$D$626,"Multi-activité (façade parmi d'autres métiers)") -> 0
A30: Total | C30: =SUM(C7:C29) -> 498 | D30: =SUM(D7:D29) -> 1 | F30: =SUM(F7:F29) -> 438 | G30: =SUM(G7:G29) -> 43 | H30: =SUM(H7:H29) -> 7 | I30: =SUM(I7:I29) -> 10
A32: Lecture : 8 codes NAF, tous dans la division 43 (travaux de construction spécialisés), regroupent 90 % des façadiers confirmés ; les 15 autres codes n'en comptent que 51 (10 %). Cibler par NAF a donc deux coûts : manquer environ 10 % des façadiers, classés sous des codes atypiques, et inclure les entreprises de ces 8 codes qui ne font pas de façade. Le premier coût est mesuré ici ; le second est estimé par un test sur un échantillon aléatoire (ligne suivante). Les couvreurs-bardeurs (43.91B, 43.99A) sont sous-représentés : beaucoup n'ont pas pu être vérifiés (voir Limites 3).
A33: Test de précision : sur 100 entreprises tirées au hasard en 43.99C, 26 ont une activité façade, dont 5 seulement en cœur de métier (voir onglet Test précision NAF). Marge d'erreur d'environ ± 8 points.

Sheet Test précision NAF
A1: Test de précision du code NAF 43.99C (maçonnerie générale)
A2: Question : parmi les entreprises classées 43.99C, combien font réellement de la façade ? (voir Limites, ligne 6)
A3: Population : 9 056 entreprises actives de 6 à 199 salariés en 43.99C (API Recherche d'entreprises, 26/09/2026), avec ou sans mot-clé dans le nom.
A4: Tirage : 100 entreprises au hasard, en deux fois (20 puis 80, graines 20260926 et 20260927, reproductibles), toutes vérifiées par un agent IA (Claude). Vérification : même règle que l'onglet Méthodologie (label RGE ADEME, activité déclarée au BODACC, site ou fiche web). Une activité façade trouvée seulement dans un résumé de recherche a été contrôlée sur la page source.
A6: N° | B6: SIREN | C6: Nom | D6: Commune | E6: Effectif (salariés) | F6: Verdict | G6: Preuve | H6: Source
A7: 1 | B7: 336520226 | C7: ROUX CABRERO ENTREPRISE GENERALE DE BATIMENT | D7: ANNONAY (07100) | E7: 20 à 49 | F7: Indice faible (non confirmé) | G7: Entreprise générale de bâtiment (groupe FAYAT). Un annuaire évoque projection de façade et ravalement, mais le site de l'entreprise n'en parle pas. | H7: https://rouxcabrero.fayat.com/
A8: 2 | B8: 879191005 | C8: SARL SEBASTIEN QUERO | D8: BOQUEHO (22170) | E8: 6 à 9 | F8: Indice faible (non confirmé) | G8: Activité déclarée : maçonnerie neuf, terrassement, assainissement, rénovation. Seul un texte générique d'annuaire évoque la restauration de façades en pierre ou brique. | H8: https://omizi.com/professionnel/sarl-sebastien-quero
A9: 3 | B9: 412854184 | C9: A.E.M. CONSTRUCTIONS | D9: PLAISIR (78370) | E9: 10 à 19 | F9: Pas d'activité façade | G9: Activité déclarée : maçonnerie, charpente, couverture, plâtrerie, isolation (fiche PagesJaunes : maçonnerie). | H9: https://www.pagesjaunes.fr/pros/07437598
A10: 4 | B10: 533821484 | C10: BVF 62 (BVF 62) | D10: EPERLECQUES (62910) | E10: 10 à 19 | F10: Pas d'activité façade | G10: Gros œuvre, plâtrerie-isolation, menuiserie, carrelage. RGE isolation intérieure, combles et fenêtres, pas ITE. | H10: https://bvf62.net/
A11: 5 | B11: 316972140 | C11: CONSTRUIRE EN PROVENCE | D11: NYONS (26110) | E11: 10 à 19 | F11: Façade parmi d'autres activités | G11: « démolition, fondation, maçonnerie, béton armé, charpente, couverture, ravalement de façade et isolation » (fiche PagesJaunes). | H11: https://www.pagesjaunes.fr/pros/05573529
A12: 6 | B12: 750188690 | C12: SCA33 | D12: BEYCHAC-ET-CAILLAU (33750) | E12: 10 à 19 | F12: Pas d'activité façade | G12: Activité déclarée : maçonnerie, rénovations, démolitions, terrassements, entretien de routes. | H12: https://annuaire-entreprises.data.gouv.fr/entreprise/sca33-750188690
A13: 7 | B13: 798439287 | C13: CAP CONSTRUCTION MEDITERRANEE | D13: NICE (06200) | E13: 10 à 19 | F13: Pas d'activité façade | G13: Gros œuvre et second œuvre. Liquidation judiciaire le 28/01/2025 (BODACC), alors que le répertoire la donne active. | H13: https://annuaire-entreprises.data.gouv.fr/entreprise/798439287
A14: 8 | B14: 828886093 | C14: N.C.E | D14: GEISPOLSHEIM (67118) | E14: 10 à 19 | F14: Indice faible (non confirmé) | G14: Maçonnerie gros œuvre ; mentionne « maçonnerie de façade » (pierre, brique), pas de ravalement, enduit ni ITE. | H14: https://www.pagesjaunes.fr/pros/58136673
A15: 9 | B15: 402580476 | C15: SARL BRITO ET FILS | D15: VALENCE (26000) | E15: 10 à 19 | F15: Indice faible (non confirmé) | G15: Maçonnerie, carrelage, isolation (fiche PagesJaunes). Un annuaire évoque des travaux de façade, sans confirmation. RGE isolation intérieure uniquement. | H15: https://www.pagesjaunes.fr/pros/07582631
A16: 10 | B16: 442992905 | C16: SARL NONQUE ENTREPRISE MARLIEN | D16: AISEREY (21110) | E16: 10 à 19 | F16: Façade parmi d'autres activités | G16: Qualification RGE « Isolation des murs par l'extérieur » en cours de validité (ADEME), en plus de la maçonnerie. | H16: https://www.france-artisan.fr/annuaire-rge/entreprise/44299290500012
A17: 11 | B17: 517394318 | C17: CORSICA TRAVAUX (CORSICA TRAVAUX) | D17: BIGUGLIA (20620) | E17: 10 à 19 | F17: Pas d'activité façade | G17: Activité déclarée : maintenance et rénovation tous corps d'état (maçonnerie, peinture, plomberie, électricité…). | H17: https://annuaire-entreprises.data.gouv.fr/entreprise/517394318
A18: 12 | B18: 503563025 | C18: AUDET FILS | D18: TARASCON (13150) | E18: 6 à 9 | F18: Pas d'activité façade | G18: Maçonnerie générale, restauration de bâtisses. RGE isolation intérieure, combles et fenêtres, pas ITE. | H18: https://audet-fils.fr/
... A106: 100 | B106: 316806223 | C106: BENAND ET CIE | D106: LA CHAPELLE-D'ABONDANCE (74360) | E106: 6 à 9 | F106: Pas d'activité façade | G106: Maçonnerie, génie civil, terrassement. | H106: https://benand.com/terrassement-enrochement/
A108: Résultat
A109: Entreprises vérifiées | F109: =COUNTA(F7:F106) -> 100
A110: Façadier (cœur de métier) | F110: =COUNTIF(F7:F106,"Façadier (cœur de métier)") -> 5
A111: Façade parmi d'autres activités | F111: =COUNTIF(F7:F106,"Façade parmi d'autres activités") -> 21
A112: Indice faible (non confirmé) | F112: =COUNTIF(F7:F106,"Indice faible (non confirmé)") -> 20
A113: Pas d'activité façade | F113: =COUNTIF(F7:F106,"Pas d'activité façade") -> 54
A114: Part avec une preuve d'activité façade (cœur de métier + parmi d'autres activités) | F114: =(F110+F111)/F109 -> 0.26
A115: Part de façadiers dont c'est le cœur de métier | F115: =F110/F109 -> 0.05
A117: Lecture : 26 entreprises sur 100 ont une activité façade prouvée ; la vraie proportion se situe probablement entre 18 % et 35 % (marge d'environ ± 8 points). Les façadiers de métier sont rares : 5 sur 100. Double vérification : chaque preuve contrôlée sur sa source, 12 « indices faibles » et 12 « pas d'activité » tirés au hasard revus par une seconde recherche.

Sheet Méthodologie
A1: Méthodologie
A2: Chaîne de traitement exécutée le 24/09/2026 avec des scripts Python, puis corrigée et complétée le 26/09/2026 (revérifications, contre-vérifications, test de précision).
A4: Étape | B4: Ce qui est fait | C4: Source | D4: Résultat (entreprises)
A5: 1. Extraction | B5: Recherche des mots-clés « facade », « ravalement », « bardage » ; filtre côté serveur : entreprises actives, tranches d'effectif 6 à 199 salariés. Chaque requête renvoie moins de 400 résultats (393, 161 et 89) : aucune troncature (limite de l'API : 10 000 résultats par requête). | C5: API Recherche d'entreprises (recherche-entreprises.api.gouv.fr) | D5: 629
A6: 2. Exclusions | B6: Retrait des noms contenant des mots hors cible (immobilier, nettoyage, conseil, holding…), en mots entiers. | C6: Règle de l'étude | D6: 4
A7: 3. Libellés NAF | B7: Ajout des libellés officiels de la nomenclature NAF rév. 2. | C7: INSEE | D7: =COUNTA(Base!$A$2:$A$626) -> 625
A8: 4. Vérification automatique | B8: Qualification RGE « isolation des murs par l'extérieur » en cours de validité, ou vocabulaire métier explicite sur le site web déclaré à l'ADEME. | C8: ADEME, liste des entreprises RGE ; sites web | D8: =COUNTIF(Base!$F$2:$F$626,"automatique (RGE*") -> 286
A9: 5. Contrôle web assisté par IA | B9: Recherche nom + commune par un agent IA (Claude, via l'outil de recherche web de Claude Code) ; lecture des résultats et des fiches (site, PagesJaunes, annuaires, objet social) ; verdict motivé avec lien, non relu un par un. Relecture humaine de 20 verdicts tirés au hasard (26/09/2026) : 18 justes (90 %), aucun faux « Confirmé ». Contre-vérification de 20 autres verdicts sur sources primaires (registres officiels, pages des entreprises) : 19 justes (95 %). | C9: Recherche web (agent IA) | D9: =COUNTIF(Base!$F$2:$F$626,"recherche web*") -> 201
A10: 6. Activité déclarée au greffe | B10: Pour les entreprises non contrôlées sur le web : lecture de l'activité déclarée au BODACC (annonces de création et de modification). Le 26/09/2026, la lecture a été étendue aux activités déclarées dans toutes les annonces : 20 entreprises supplémentaires confirmées. | C10: BODACC (API DILA) | D10: =COUNTIF(Base!$F$2:$F$626,"BODACC*") -> 72
A11: 7. Procédures collectives | B11: Dernier jugement significatif (redressement, sauvegarde, liquidation, plan) pour toutes les entreprises. Les procédures antérieures à 2023 ont été revérifiées manuellement sur le BODACC (5 entreprises : 3 réintégrées aux prospects, 1 passée en liquidation). Les 14 entreprises sous plan ou « autre jugement » ont aussi été revérifiées : 2 étaient passées en liquidation (BIG RAVALEMENT, DS RAVALEMENT). | C11: BODACC (API DILA) | D11: =COUNTIF(Base!$P$2:$P$626,"?*") -> 58
A12: 8. Non vérifiées | B12: Entreprises restées sans contrôle web ni activité BODACC exploitable : l'outil de recherche web plafonne à 200 recherches par session, quota atteint. | C12: — | D12: =COUNTIF(Base!$F$2:$F$626,"non vérifié*") -> 47
A13: 9. Classement par NAF seul | B13: NAF hors du bâtiment (restauration, commerce…) : classées hors cible sans recherche web. Les 7 entreprises d'abord exclues pour un NAF « adjacent » ont été revérifiées au BODACC (étape 6) : 6 hors cible, 1 confirmée. | C13: INSEE (code NAF) | D13: =COUNTIF(Base!$F$2:$F$626,"automatique (NAF*") -> 19
A14: Total classées | B14: Étapes 4, 5, 6, 8 et 9 : chaque entreprise est comptée une seule fois. | D14: =D8+D9+D10+D12+D13 -> 625
A15: Règles de classement
A16: Classement | B16: Définition | C16: Exemples de preuves | D16: Nombre
A17: Confirmé | B17: Au moins une preuve explicite d'une activité façade (ravalement, enduits, ITE, bardage, façade légère). | C17: RGE ITE ; site ou fiche décrivant l'activité ; objet social déclaré au greffe. | D17: =COUNTIF(Base!$C$2:$C$626,A17) -> 498
A18: Probable | B18: Nom et NAF cohérents, mais aucune source décrivant le métier (annuaires recopiant le registre), ou entreprise non vérifiée. | C18: Mot-clé dans le nom + NAF du bâtiment. | D18: =COUNTIF(Base!$C$2:$C$626,A18) -> 64
A19: Douteux | B19: Les sources décrivent un autre métier principal, malgré un nom évoquant la façade. | C19: Menuiserie, plâtrerie, étanchéité seule, entreprise générale. | D19: =COUNTIF(Base!$C$2:$C$626,A19) -> 26
A20: Hors cible (autre métier) | B20: Métier du bâtiment clairement différent. | C20: Échafaudagiste, menuisier alu, fabricant, installateur PAC. | D20: =COUNTIF(Base!$C$2:$C$626,A20) -> 9
A21: Hors cible (adjacent) | B21: Fabricant, bureau d'études, architecte : lié à la façade mais pas poseur. | C21: NAF 71.11Z, 71.12B, 22.23Z, 46.73A. | D21: =COUNTIF(Base!$C$2:$C$626,A21) -> 5
A22: Hors cible | B22: Hors du bâtiment, holding ou collectivité ; le mot-clé figurait ailleurs que dans l'activité. | C22: Restaurant, fleuriste, commune (« opération façades »). | D22: =COUNTIF(Base!$C$2:$C$626,A22) -> 23
A23: Total | D23: =SUM(D17:D22) -> 625

Sheet Limites
A1: Limites de l'étude
A2: À lire avant d'utiliser les chiffres. Chaque limite indique son effet sur les résultats.
A4: # | B4: Limite | C4: Description | D4: Effet sur les résultats | E4: Ampleur | F4: Comment la lever
A5: 1 | B5: Rappel limité au nom | C5: Seules les entreprises trouvées par la recherche de l'API sur « façade », « ravalement » ou « bardage » sont captées, en pratique surtout celles dont le nom ou l'enseigne contient ces mots. Un façadier nommé « SARL Dupont » est en général absent. | D5: Le nombre total de façadiers en France est sous-estimé. La dispersion NAF est mesurée sur cet échantillon, qui peut différer des façadiers sans mot-clé dans le nom. | E5: Non mesurable avec cette méthode. | F5: Partir de la base RGE ADEME (domaine ITE) et d'annuaires métiers, indépendamment du nom.
A6: 2 | B6: Précision du NAF peu mesurée | C6: L'étude montre que les façadiers sont dispersés sur de nombreux codes NAF. Elle ne mesure pas précisément quelle part des entreprises d'un code NAF donné sont des façadiers ; un test sur 100 entreprises en 43.99C en donne un ordre de grandeur (colonne Ampleur). | D6: Le test donne un ordre de grandeur pour le code 43.99C (environ 1 entreprise sur 4), pas une mesure précise ; les autres codes NAF ne sont pas mesurés. | E6: Test sur 100 entreprises tirées au hasard en 43.99C : 26 ont une activité façade (vraie proportion probablement entre 18 % et 35 %). | F6: Étendre le test à 43.34Z et 43.29A, et à un échantillon plus grand.
A7: 3 | B7: Vérification incomplète | C7: Une partie des entreprises n'a pu être contrôlée ni sur le web ni via le BODACC : l'outil de recherche web utilisé (Claude Code) plafonne à 200 recherches par session. | D7: Ces entreprises restent « Probable » ; le nombre de confirmés est un minimum. Elles ne sont pas réparties au hasard : la vérification a suivi l'ordre façade, ravalement, bardage, et 24 des 83 entreprises « bardage » restent non vérifiées (1 sur 392 pour « façade »). Les couvreurs-bardeurs (NAF 43.91B, 43.99A) sont donc encore sous-représentés parmi les confirmés et dans la dispersion NAF. | E7: =COUNTIF(Base!$F$2:$F$626,"non vérifié*")&" entreprises non vérifiées" -> 47 entreprises non vérifiées | F7: Poursuivre le contrôle web sur les « Probable ».
A8: 4 | B8: Nature de la preuve | C8: « Confirmé » signifie qu'une source atteste une activité façade, pas qu'elle est l'activité principale. Plusieurs annuaires recopient l'objet social ; l'activité BODACC est celle déclarée à la création ou lors d'une modification. | D8: Quelques entreprises multi-activités peuvent être surclassées. | E8: =COUNTIFS(Base!$C$2:$C$626,"Confirmé",Base!$D$2:$D$626,"Multi*")&" multi-activités identifiées" -> 10 multi-activités identifiées | F8: Entretien téléphonique ou analyse des chantiers réalisés.
A9: 5 | B9: Verdicts produits par un agent IA | C9: Les 201 verdicts web ont été rendus par un agent IA (Claude) à partir de résultats de recherche, selon les règles de l'onglet Méthodologie, sans relecture humaine systématique. | D9: Erreurs individuelles possibles, en particulier entre « Probable » et « Douteux » ; une preuve peut venir d'un résumé de recherche plutôt que de la page citée. Sur 40 verdicts vérifiés, 3 erreurs : 2 excès de prudence (un façadier classé « Douteux », un peintre classé « Probable » au lieu de « Douteux ») et 1 faux « Confirmé » (un peintre sans preuve de façade). Toutes corrigées. | E9: =COUNTIF(Base!$F$2:$F$626,"recherche web*")&" verdicts rendus par l'agent IA, chacun avec sa source" -> 201 verdicts rendus par l'agent IA, chacun avec sa source | F9: Fait le 26/09/2026 sur 40 verdicts tirés au hasard : 20 relus par un humain (18 justes) et 20 contre-vérifiés sur sources primaires (19 justes), soit 37 sur 40 (93 %).
A10: 6 | B10: Effectifs | C10: Les effectifs sont des tranches INSEE publiées avec un décalage d'un à deux ans. Certains annuaires affichent des effectifs plus faibles. | D10: Quelques entreprises peuvent être aujourd'hui sous 6 salariés. | E10: Ponctuel | F10: Contrôler l'effectif au moment de la prospection.
A11: 7 | B11: Définition du façadier | C11: Les couvreurs-étancheurs faisant du bardage et les poseurs de façade légère sont inclus dans les confirmés, mais segmentés. La colonne Spécialité est attribuée automatiquement (nom, NAF, mots de la preuve) : un couvreur dont le nom contient « façade » peut être rangé en cœur de métier. | D11: Le total dépend de la définition retenue ; la répartition par spécialité est indicative (la part « cœur de métier » est un maximum). | E11: =(COUNTIFS(Base!$C$2:$C$626,"Confirmé",Base!$D$2:$D$626,"Couvreur*")+COUNTIFS(Base!$C$2:$C$626,"Confirmé",Base!$D$2:$D$626,"Façade légère*"))&" entreprises concernées" -> 50 entreprises concernées | F11: Filtrer la colonne Spécialité selon la définition souhaitée.
A12: 8 | B12: Données datées | C12: Statuts juridiques et procédures collectives relevés au 24/09/2026. Alertes anciennes et plans en cours revérifiés manuellement le 26/09/2026. | D12: La situation évolue vite pour les entreprises en procédure. | E12: — | F12: Revérifier le BODACC avant toute campagne.
A13: 9 | B13: Mots-clés secondaires non utilisés | C13: « Vêtage », « vêture », « enduit » et « isolation thermique extérieure » n'ont pas été recherchés. Exemple : SOGEP (Société Générale d'Enduits Parisiens), façadier trouvé lors du test de précision NAF, est absent de l'étude. | D13: Quelques spécialistes de l'enveloppe sont absents. | E13: — | F13: Relancer l'extraction avec ces mots-clés.

Sheet Recommandations
A1: Recommandations et prochaines étapes
A3: Priorité | B3: Action | C3: Pourquoi | D3: Effort
A4: 1 | B4: Prospecter l'onglet Prospects en priorité : les entreprises en procédure collective en sont déjà écartées. | C4: Liste vérifiée, sans alerte juridique. | D4: Immédiat
A5: 2 | B5: Ne pas utiliser le code NAF comme critère de ciblage principal ; s'appuyer sur la qualification RGE ITE et l'activité déclarée. | C5: Aucun code ne suffit seul : il en faut 8 pour couvrir 90 % des façadiers, et ces codes sont partagés avec d'autres métiers. | D5: Faible
A6: 3 | B6: Terminer la vérification des entreprises « Probable » (contrôle web). | C6: Porte le nombre de confirmés à sa valeur réelle. | D6: Faible : relancer une session avec un quota de recherches plus élevé (environ 2 h 30 à la main)
A7: 4 | B7: Élargir le rappel : extraire toutes les entreprises RGE « isolation des murs par l'extérieur » de 6 à 199 salariés, quel que soit leur nom. | C7: Capte les façadiers sans mot-clé dans le nom. | D7: Moyen
A8: 5 | B8: Mesurer la précision du NAF sur un échantillon aléatoire de 43.99C, 43.34Z et 43.29A. Premier test réalisé sur 100 entreprises en 43.99C (onglet Test précision NAF) ; à étendre à 43.34Z et 43.29A. | C8: Chiffre le coût d'un ciblage par NAF (faux positifs). | D8: Moyen
A9: 6 | B9: Revérifier le BODACC juste avant chaque campagne. | C9: Les procédures collectives évoluent vite. | D9: Faible

Sheet Prospects
A1: Prospects : façadiers confirmés sans alerte juridique
A2: Filtrer la colonne Spécialité pour appliquer la définition souhaitée.
A4: SIREN | B4: Nom | C4: Classement | D4: Spécialité | E4: Alerte | F4: Code NAF | G4: Libellé NAF | H4: Effectif (salariés) | I4: Commune | J4: Code postal | K4: Département | L4: Méthode de vérification | M4: Preuve | N4: Source
A5: 851694190 | B5: CAVIEUX FACADES | C5: Confirmé | D5: Façadier (ravalement, enduits, ITE, bardage) | F5: 43.99C | G5: Travaux de maçonnerie générale et gros œuvre de bâtiment | H5: 6 à 9 | I5: SAINT-ANDRE-DE-CORCY | J5: 01390 | K5: 01 | L5: automatique (RGE ADEME / site web) | M5: RGE isolation des murs par l'extérieur (ADEME) ; site web : enduit, facade, ite, ravalement ; mot-clé dans le nom/enseigne ; NAF 43.99C BTP cohérent | N5: https://data.ademe.fr/datasets/liste-des-entreprises-rge-2
A6: 419678396 | B6: E.R.T.B.I. (ERTBI FACADES ENVIRONNEMENT) | C6: Confirmé | D6: Multi-activité (façade parmi d'autres métiers) | F6: 43.99B | G6: Travaux de montage de structures métalliques | H6: 6 à 9 | I6: CHARNOZ-SUR-AIN | J6: 01800 | K6: 01 | L6: recherche web (agent IA) | M6: échafaudage + travaux de façade extérieure, plâtrerie (multi-activité) | N6: https://lyon-entreprises.com/Annuaire/ERTBI-FACADES-ENVIRONNEMENT-20427/coordonnees-caluire-et-cuire.html
A7: 538058041 | B7: REIS BARDAGE | C7: Confirmé | D7: Couvreur / étancheur faisant du bardage | F7: 43.91B | G7: Travaux de couverture par éléments | H7: 6 à 9 | I7: LA BOISSE | J7: 01120 | K7: 01 | L7: BODACC (activité déclarée au greffe) | M7: activité déclarée : Travaux de couverture et de bardage. | N7: https://www.bodacc.fr/ (SIREN 538058041)
A8: 915208334 | B8: TECHNO BARDAGE | C8: Confirmé | D8: Couvreur / étancheur faisant du bardage | F8: 43.91B | G8: Travaux de couverture par éléments | H8: 6 à 9 | I8: MONTLUEL | J8: 01120 | K8: 01 | L8: BODACC (activité déclarée au greffe) | M8: activité déclarée : couverture et bardage | N8: https://www.bodacc.fr/ (SIREN 915208334)
A9: 828285437 | B9: CFP TECHNI-FACADES | C9: Confirmé | D9: Façadier (ravalement, enduits, ITE, bardage) | F9: 43.99C | G9: Travaux de maçonnerie générale et gros œuvre de bâtiment | H9: 6 à 9 | I9: BRUGHEAS | J9: 03700 | K9: 03 | L9: automatique (RGE ADEME / site web) | M9: RGE isolation des murs par l'extérieur (ADEME) ; mot-clé dans le nom/enseigne ; NAF 43.99C BTP cohérent | N9: https://data.ademe.fr/datasets/liste-des-entreprises-rge-2
A10: 978246767 | B10: DK FACADE ITE PEINTURE | C10: Confirmé | D10: Façadier (ravalement, enduits, ITE, bardage) | F10: 43.99C | G10: Travaux de maçonnerie générale et gros œuvre de bâtiment | H10: 6 à 9 | I10: MANOSQUE | J10: 04100 | K10: 04 | L10: recherche web (agent IA) | M10: ravalement, ITE, peinture | N10: https://servicesartisans.fr/services/facadier/manosque/dk-facade-ite-peinture-978246767
A11: 814514162 | B11: K 2 (CONCEPT FACADES) | C11: Confirmé | D11: Façadier (ravalement, enduits, ITE, bardage) | F11: 43.99C | G11: Travaux de maçonnerie générale et gros œuvre de bâtiment | H11: 20 à 49 | I11: BIOT | J11: 06410 | K11: 06 | L11: recherche web (agent IA) | M11: enseigne CONCEPT FACADES : ravalement, peinture, ITE ; 20-49 salariés | N11: https://annuaire-entreprises.data.gouv.fr/entreprise/814514162
A12: 847633633 | B12: SASU BATI PROJECT FACADES | C12: Confirmé | D12: Façadier (ravalement, enduits, ITE, bardage) | F12: 43.33Z | G12: Travaux de revêtement des sols et des murs | H12: 6 à 9 | I12: ANTIBES | J12: 06600 | K12: 06 | L12: recherche web (agent IA) | M12: ravalement / nettoyage de façades (+ négoce carrelage) | N12: https://www.pagesjaunes.fr/pros/60786535
A13: 837629419 | B13: SILLA FACADES | C13: Confirmé | D13: Façadier (ravalement, enduits, ITE, bardage) | F13: 43.99C | G13: Travaux de maçonnerie générale et gros œuvre de bâtiment | H13: 20 à 49 | I13: CAGNES-SUR-MER | J13: 06800 | K13: 06 | L13: recherche web (agent IA) | M13: travaux de façade : nettoyage, isolation thermique | N13: https://www.pagesjaunes.fr/pros/55671292
A14: 819985979 | B14: FACADES A.Z. | C14: Confirmé | D14: Façadier (ravalement, enduits, ITE, bardage) | F14: 43.99C | G14: Travaux de maçonnerie générale et gros œuvre de bâtiment | H14: 10 à 19 | I14: SAINT-DIDIER-SOUS-AUBENAS | J14: 07200 | K14: 07 | L14: automatique (RGE ADEME / site web) | M14: RGE isolation des murs par l'extérieur (ADEME) ; mot-clé dans le nom/enseigne ; NAF 43.99C BTP cohérent | N14: https://data.ademe.fr/datasets/liste-des-entreprises-rge-2
A15: 433256237 | B15: FACADES ARDECHOISES | C15: Confirmé | D15: Façadier (ravalement, enduits, ITE, bardage) | F15: 43.99A | G15: Travaux d'étanchéification | H15: 20 à 49 | I15: ANNONAY | J15: 07100 | K15: 07 | L15: automatique (RGE ADEME / site web) | M15: RGE isolation des murs par l'extérieur (ADEME) ; site web : enduit, ravalement ; mot-clé dans le nom/enseigne ; NAF 43.99A BTP cohérent | N15: https://data.ademe.fr/datasets/liste-des-entreprises-rge-2
A16: 798080495 | B16: SUD ARDECHE FACADES | C16: Confirmé | D16: Façadier (ravalement, enduits, ITE, bardage) | F16: 43.99C | G16: Travaux de maçonnerie générale et gros œuvre de bâtiment | H16: 6 à 9 | I16: AUBENAS | J16: 07200 | K16: 07 | L16: automatique (RGE ADEME / site web) | M16: RGE isolation des murs par l'extérieur (ADEME) ; mot-clé dans le nom/enseigne ; NAF 43.99C BTP cohérent | N16: https://data.ademe.fr/datasets/liste-des-entreprises-rge-2
... A469: 330940172 | B469: SOC KOUROU BARDAGE (SKB) | C469: Confirmé | D469: Couvreur / étancheur faisant du bardage | F469: 43.91B | G469: Travaux de couverture par éléments | H469: 6 à 9 | I469: KOUROU | J469: 97310 | K469: 973 | L469: BODACC (activité déclarée au greffe) | M469: activité déclarée : non précisée / bardage, entretien, couverture, étanchéité et tout ce qui touche à l'industrie des travaux publics | N469: https://www.bodacc.fr/ (SIREN 330940172)

Sheet À vérifier et exclus
A1: Entreprises à vérifier, douteuses, hors cible ou sous alerte
A2: Probables et douteux à vérifier ; hors cible avec motif ; confirmés en procédure collective.
A4: SIREN | B4: Nom | C4: Classement | D4: Spécialité | E4: Alerte | F4: Code NAF | G4: Libellé NAF | H4: Effectif (salariés) | I4: Commune | J4: Code postal | K4: Département | L4: Méthode de vérification | M4: Preuve | N4: Source
A5: 814774246 | B5: SOLUTIONS POSES FACADES (SPF) (SPF) | C5: Douteux | F5: 43.32B | G5: Travaux de menuiserie métallique et serrurerie | H5: 6 à 9 | I5: ETAMPES-SUR-MARNE | J5: 02400 | K5: 02 | L5: recherche web (agent IA) | M5: activité décrite = menuiserie métallique / serrurerie ; façade non attestée | N5: https://www.pappers.fr/entreprise/spf-solutions-poses-facades-814774246
A6: 885361626 | B6: D.A.F. COUVERTURE BARDAGE | C6: Probable | F6: 43.91B | G6: Travaux de couverture par éléments | H6: 10 à 19 | I6: VICHY | J6: 03200 | K6: 03 | L6: non vérifié (quota de 200 recherches web atteint) | M6: mot-clé dans le nom/enseigne ; NAF 43.91B BTP cohérent
A7: 210400453 | B7: COMMUNE DE CERESTE-EN-LUBERON | C7: Hors cible | F7: 84.11Z | G7: Administration publique générale | H7: 20 à 49 | I7: CERESTE-EN-LUBERON | J7: 04280 | K7: 04 | L7: recherche web (agent IA) | M7: collectivité (commune) — enseigne « opération façade » | N7: https://annuaire-entreprises.data.gouv.fr/entreprise/210400453
A8: 351963350 | B8: SOCIETE DE RAVALEMENT D'ISOLATION ET D'ETANCHEITE (SORIE) | C8: Confirmé | D8: Façadier (ravalement, enduits, ITE, bardage) | E8: Vigilance : redressement judiciaire en cours | F8: 43.34Z | G8: Travaux de peinture et vitrerie | H8: 10 à 19 | I8: LA ROQUETTE-SUR-SIAGNE | J8: 06550 | K8: 06 | L8: BODACC (activité déclarée au greffe) | M8: activité déclarée : entreprise d'étanchéité en bâtiment de ravalement de bâtiments. / Entreprise d'étanchéité en bâtiment de ravalement de bâtiments | N8: https://www.bodacc.fr/ (SIREN 351963350)
A9: 786020206 | B9: ETABLISSEMENTS WARSMANN | C9: Hors cible (autre métier) | F9: 43.32B | G9: Travaux de menuiserie métallique et serrurerie | H9: 20 à 49 | I9: NOUZONVILLE | J9: 08700 | K9: 08 | L9: recherche web (agent IA) | M9: menuiserie aluminium et serrurerie, structures métalliques ; façade non attestée | N9: https://www.warsmann.fr/
A10: 828250373 | B10: OCCITANIE BATIMENT FACADE | C10: Probable | F10: 43.99C | G10: Travaux de maçonnerie générale et gros œuvre de bâtiment | H10: 10 à 19 | I10: MONTREDON-DES-CORBIERES | J10: 11100 | K10: 11 | L10: recherche web (agent IA) | M10: sources = annuaires uniquement ; NAF maçonnerie | N10: https://www.pappers.fr/entreprise/occitanie-batiment-facade-828250373
A11: 887981249 | B11: SEBAPROMOTION | C11: Hors cible | F11: 70.22Z | G11: Conseil pour les affaires et autres conseils de gestion | H11: 10 à 19 | I11: SEBAZAC-CONCOURES | J11: 12740 | K11: 12 | L11: automatique (NAF hors BTP) + BODACC | M11: NAF 70.22Z hors BTP ; activité déclarée : toutes prestations de services en matière commerciale et de gestion, distribution et commercialisation de produits, objets, marchandises pour le compte de tous tiers | N11: https://www.bodacc.fr/ (SIREN 887981249)
A12: 902657063 | B12: AYDIN FACADES | C12: Probable | F12: 43.99C | G12: Travaux de maçonnerie générale et gros œuvre de bâtiment | H12: 10 à 19 | I12: PEYPIN | J12: 13124 | K12: 13 | L12: recherche web (agent IA) | M12: activité décrite = maçonnerie de rénovation ; façade non explicite | N12: https://peypin.localbiz.fr/fiche-aydin-facades-13073-90265706300019
A13: 825010796 | B13: CHAPES CARRELAGES BRISENO (POSE DE PIERRES ET DE TOUT TYPE DE REVETEMENT DE SOLS MURS ET FACADES) | C13: Hors cible (autre métier) | F13: 43.33Z | G13: Travaux de revêtement des sols et des murs | H13: 6 à 9 | I13: BOULBON | J13: 13150 | K13: 13 | L13: recherche web (agent IA) | M13: chapes, carrelage, pose de pierres ; pas façadier | N13: https://www.pappers.fr/entreprise/chapes-carrelages-briseno-825010796
A14: 815129960 | B14: CHARPENTE COUVERTURE BARDAGE (CCB) | C14: Probable | F14: 43.99B | G14: Travaux de montage de structures métalliques | H14: 10 à 19 | I14: BERRE-L'ETANG | J14: 13130 | K14: 13 | L14: non vérifié (quota de 200 recherches web atteint) | M14: mot-clé dans le nom/enseigne ; NAF 43.99B BTP cohérent
A15: 527988257 | B15: LAVARENNE | C15: Hors cible | F15: 10.71C | G15: Boulangerie et boulangerie-pâtisserie | H15: 20 à 49 | I15: VENELLES | J15: 13770 | K15: 13 | L15: automatique (NAF hors BTP) | M15: NAF 10.71C hors BTP
A16: 894901479 | B16: RIP 13 RAVALEMENT ISOLATION PEINTURE 13 | C16: Probable | F16: 43.33Z | G16: Travaux de revêtement des sols et des murs | H16: 6 à 9 | I16: MARSEILLE | J16: 13014 | K16: 13 | L16: non vérifié (quota de 200 recherches web atteint) | M16: mot-clé dans le nom/enseigne ; NAF 43.33Z BTP cohérent
A17: 520980517 | B17: ATLANTIQUE BARDAGE | C17: Douteux | F17: 43.29A | G17: Travaux d'isolation | H17: 6 à 9 | I17: PERIGNY | J17: 17180 | K17: 17 | L17: BODACC (activité déclarée au greffe) | M17: activité déclarée sans mention façade : Travaux d'amélioration thermique, amélioration de l'habitat, négoce de matériaux d'isolation | N17: https://www.bodacc.fr/ (SIREN 520980517)
A18: 481411882 | B18: CITYA COTE DE BEAUTE (CITYA COTE DE BEAUTE) | C18: Hors cible | F18: 68.32A | G18: Administration d'immeubles et autres biens immobiliers | H18: 10 à 19 | I18: ROYAN | J18: 17200 | K18: 17 | L18: automatique (NAF hors BTP) + BODACC | M18: NAF 68.32A hors BTP ; activité déclarée : transaction immobilière, gestion immobilière et syndic de copropriété / agence immobilière, transaction sur appartement et maison, gestion et location | N18: https://www.bodacc.fr/ (SIREN 481411882)
A19: 534295613 | B19: JBC FACADES | C19: Douteux | E19: NE PAS PROSPECTER : liquidation judiciaire | F19: 43.31Z | G19: Travaux de plâtrerie | H19: 6 à 9 | I19: ARS-EN-RE | J19: 17590 | K19: 17 | L19: recherche web (agent IA) | M19: activité déclarée plâtrerie ; aucune trace d'activité façade | N19: https://www.mon-platrier.fr/entreprise/jbc-facades-534295613/
A20: 500592092 | B20: MG+ARCHITECTES | C20: Hors cible (adjacent) | F20: 71.11Z | G20: Activités d'architecture | H20: 6 à 9 | I20: SAINTES | J20: 17100 | K20: 17 | L20: BODACC (activité déclarée au greffe) | M20: activité déclarée : profession d'architecte, urbaniste et paysagiste | N20: https://www.bodacc.fr/ (SIREN 500592092)
A21: 409596244 | B21: NOUVELLE AQUITAINE RAVALEMENT (NAR) | C21: Confirmé | D21: Façadier (ravalement, enduits, ITE, bardage) | E21: Radiée au BODACC | F21: 43.34Z | G21: Travaux de peinture et vitrerie | H21: 10 à 19 | I21: ROYAN | J21: 17200 | K21: 17 | L21: automatique (RGE ADEME / site web) | M21: RGE isolation des murs par l'extérieur (ADEME) ; mot-clé dans le nom/enseigne ; NAF 43.34Z BTP cohérent | N21: https://data.ademe.fr/datasets/liste-des-entreprises-rge-2
A22: 445343718 | B22: RAVALEMENT DE FRANCE 17 (R.D.F. 17) | C22: Douteux | F22: 43.33Z | G22: Travaux de revêtement des sols et des murs | H22: 10 à 19 | I22: SAINT-MEDARD-D'AUNIS | J22: 17220 | K22: 17 | L22: BODACC (activité déclarée au greffe) | M22: activité déclarée sans mention façade : activité de zinguerie, gouttière aluminium, couverture de bâtiments, pose de cloisons sèches, tous travaux de fabrication, pose et réparation dans lesdits domaines. | N22: https://www.bodacc.fr/ (SIREN 445343718)
A23: 844247460 | B23: RAVALEMENT DE FRANCE 44 (R.D.F. 44) | C23: Confirmé | D23: Façadier (ravalement, enduits, ITE, bardage) | E23: NE PAS PROSPECTER : liquidation judiciaire | F23: 43.39Z | G23: Autres travaux de finition | H23: 10 à 19 | I23: SAINT-MEDARD-D'AUNIS | J23: 17220 | K23: 17 | L23: BODACC (activité déclarée au greffe) | M23: activité déclarée : réalisation d'enduit de façades de sablage de façades nettoyage de façades peinture en bâtiment | N23: https://www.bodacc.fr/ (SIREN 844247460)
A24: 499253219 | B24: ARCOFA - ARCHITECTURES CONSTRUCTION FACADES | C24: Hors cible | F24: 64.20Z | G24: Activités des sociétés holding | H24: 20 à 49 | I24: OUGES | J24: 21600 | K24: 21 | L24: recherche web (agent IA) | M24: holding (NAF 64.20Z) ; pas d'activité opérationnelle propre | N24: https://www.pappers.fr/entreprise/arcofa-architectures-construction-facades-499253219
A25: 879989101 | B25: QECB (QECB-ETANCHEITE-COUVERTURE-BARDAGE) | C25: Probable | F25: 43.91B | G25: Travaux de couverture par éléments | H25: 6 à 9 | I25: QUESSOY | J25: 22120 | K25: 22 | L25: non vérifié (quota de 200 recherches web atteint) | M25: mot-clé dans le nom/enseigne ; NAF 43.91B BTP cohérent
A26: 492274543 | B26: MF HABILLEZ VOS FACADES | C26: Confirmé | D26: Façadier (ravalement, enduits, ITE, bardage) | E26: NE PAS PROSPECTER : plan de cession | F26: 43.99C | G26: Travaux de maçonnerie générale et gros œuvre de bâtiment | H26: 20 à 49 | I26: MALATAVERNE | J26: 26780 | K26: 26 | L26: recherche web (agent IA) | M26: ravalement, enduits, bardage (devenu Indigo MF, Indigo Groupe) | N26: https://www.indigogroupe.fr/details-indigo+mf-765
A27: 309124477 | B27: POMPES FUNEBRES ET MARBRERIE BERTHELOT (POMPES FUNEBRES ET MARBRERIE BERTHELOT) | C27: Hors cible | F27: 96.03Z | G27: Services funéraires | H27: 100 à 199 | I27: GISORS | J27: 27140 | K27: 27 | L27: automatique (NAF hors BTP) + BODACC | M27: NAF 96.03Z hors BTP ; activité déclarée : Pompes funèbres, marbrerie, vente au détail de fleurs artificielles et naturelles et ornements funéraires. / Pompes funèbres, marbrerie, vente au détail de fleurs Artificilelles et naturelles et ornements funéraires. / pompes funèbres marbrerie vente au détails de fleur artificielles et naturelles et ornement funéraires. / pompes funèbres marbrerie vente au détail de fleur artificielles et naturel | N27: https://www.bodacc.fr/ (SIREN 309124477)
A28: 832085773 | B28: N'CO (LORENOVE, NCO FACADE) | C28: Hors cible (autre métier) | F28: 46.13Z | G28: Intermédiaires du commerce en bois et matériaux de construction | H28: 6 à 9 | I28: VERNOUILLET | J28: 28500 | K28: 28 | L28: recherche web (agent IA) | M28: franchise Lorenove : négoce/pose de menuiseries (fenêtres) | N28: https://www.fenetres-lorenove.fr/actualite-offres/nco-lorenove-votre-expert-en-menuiseries-a-dreux
A29: 509730743 | B29: SERVICE ASSISTANCE BARDAGE ETANCHEITE (SABE) | C29: Confirmé | D29: Couvreur / étancheur faisant du bardage | E29: NE PAS PROSPECTER : liquidation judiciaire | F29: 43.99A | G29: Travaux d'étanchéification | H29: 6 à 9 | I29: LES VILLAGES VOVEENS | J29: 28150 | K29: 28 | L29: BODACC (activité déclarée au greffe) | M29: activité déclarée : Bardage étanchéité | N29: https://www.bodacc.fr/ (SIREN 509730743)
A30: 840902183 | B30: JOAQUIM SOUSA ANDRADE (JA CHARPENTE BARDAGE) | C30: Probable | F30: 43.91A | G30: Travaux de charpente | H30: 6 à 9 | I30: BASTIA | J30: 20200 | K30: 2B | L30: non vérifié (quota de 200 recherches web atteint) | M30: mot-clé dans le nom/enseigne ; NAF 43.91A BTP cohérent
A31: 492849252 | B31: M.G.P. CONSTRUCTION - RENOVATION - FACADES | C31: Douteux | F31: 43.99C | G31: Travaux de maçonnerie générale et gros œuvre de bâtiment | H31: 10 à 19 | I31: SAINT-COME-ET-MARUEJOLS | J31: 30870 | K31: 30 | L31: recherche web (agent IA) | M31: activité décrite = isolation intérieure + couverture/charpente | N31: https://www.pappers.fr/entreprise/mgp-construction-renovation-facades-492849252
A32: 533835260 | B32: SAINT GENIES BATIMENT FACADES - SGBF (SGBF) | C32: Confirmé | D32: Façadier (ravalement, enduits, ITE, bardage) | E32: Vigilance : sauvegarde en cours | F32: 43.99C | G32: Travaux de maçonnerie générale et gros œuvre de bâtiment | H32: 10 à 19 | I32: SAINT-GENIES-DE-MALGOIRES | J32: 30190 | K32: 30 | L32: recherche web (agent IA) | M32: réhabilitation de façades, ITE | N32: https://www.pagesjaunes.fr/pros/55608996
A33: 833611585 | B33: BRL FACADES | C33: Confirmé | D33: Façadier (ravalement, enduits, ITE, bardage) | E33: Vigilance : redressement judiciaire en cours | F33: 43.99C | G33: Travaux de maçonnerie générale et gros œuvre de bâtiment | H33: 10 à 19 | I33: TOULOUSE | J33: 31100 | K33: 31 | L33: recherche web (agent IA) | M33: façadier (enduits, rénovation façade, ITE) ; EN REDRESSEMENT JUDICIAIRE | N33: https://www.brl-facades-toulouse.fr/
A34: 397941162 | B34: ENTREPRISE DE TRAVAUX ET DE RAVALEMENT (ETR) | C34: Probable | F34: 43.39Z | G34: Autres travaux de finition | H34: 6 à 9 | I34: PLAISANCE-DU-TOUCH | J34: 31830 | K34: 31 | L34: non vérifié (quota de 200 recherches web atteint) | M34: mot-clé dans le nom/enseigne ; NAF 43.39Z BTP cohérent
A35: 534958327 | B35: NATUREL FACADES (NATUREL FACADES) | C35: Confirmé | D35: Façadier (ravalement, enduits, ITE, bardage) | E35: Vigilance : redressement judiciaire en cours | F35: 43.31Z | G35: Travaux de plâtrerie | H35: 6 à 9 | I35: SEYSSES | J35: 31600 | K35: 31 | L35: recherche web (agent IA) | M35: enduits décoratifs de façade + ITE (neuf/rénovation) | N35: https://juniorfacades.fr/
A36: 810036244 | B36: SARL SPR (SOL PEINTURE RAVALEMENT) | C36: Douteux | F36: 43.31Z | G36: Travaux de plâtrerie | H36: 6 à 9 | I36: TOULOUSE | J36: 31200 | K36: 31 | L36: BODACC (activité déclarée au greffe) | M36: activité déclarée sans mention façade : pose de plaques de plâtre, peinture, carrelage, revêtement de sol, maçonnerie générale de second oeuvre / Maçonnerie générale. | N36: https://www.bodacc.fr/ (SIREN 810036244)
A37: 517550679 | B37: ICNERGIE (AQUITAINE BARDAGE COUVERTURE&QUOT;) | C37: Hors cible | F37: 70.22Z | G37: Conseil pour les affaires et autres conseils de gestion | H37: 6 à 9 | I37: LORMONT | J37: 33310 | K37: 33 | L37: automatique (NAF hors BTP) + BODACC | M37: mot-clé dans le nom/enseigne ; NAF 70.22Z hors BTP ; activité déclarée : conseil et distribution de produits d'économie d'énergie. | N37: https://www.bodacc.fr/ (SIREN 517550679)
A38: 472202845 | B38: SOC RENOVATION ENTRETIEN FACADES BETON | C38: Confirmé | D38: Façadier (ravalement, enduits, ITE, bardage) | E38: NE PAS PROSPECTER : plan de cession | F38: 43.29A | G38: Travaux d'isolation | H38: 50 à 99 | I38: LORMONT | J38: 33310 | K38: 33 | L38: recherche web (agent IA) | M38: SOREFAB : rénovation/étanchéité de façades béton, 50-99 salariés | N38: https://www.prodestravaux.com/entreprise/47220284500112
A39: 952917441 | B39: ABD FACADE | C39: Probable | F39: 43.34Z | G39: Travaux de peinture et vitrerie | H39: 10 à 19 | I39: CLERMONT-L'HERAULT | J39: 34800 | K39: 34 | L39: recherche web (contre-vérification) | M39: peintre (peinture intérieure et extérieure, enduits décoratifs) ; aucune source ne décrit de travaux de façade : reclassé « Probable » lors de la contre-vérification (26/09/2026) | N39: https://guide-de-l-habitat.fr/artisans/clermont-l-herault/peintre/abd-facade/
A40: 837604297 | B40: ALS FACADES (ALS FACADES) | C40: Probable | F40: 43.34Z | G40: Travaux de peinture et vitrerie | H40: 6 à 9 | I40: MARAUSSAN | J40: 34370 | K40: 34 | L40: non vérifié (quota de 200 recherches web atteint) | M40: mot-clé dans le nom/enseigne ; NAF 43.34Z BTP cohérent
A41: 910405794 | B41: AMI FACADE | C41: Probable | F41: 43.99C | G41: Travaux de maçonnerie générale et gros œuvre de bâtiment | H41: 6 à 9 | I41: MONTPELLIER | J41: 34080 | K41: 34 | L41: recherche web (agent IA) | M41: sources = annuaires uniquement (créée 2022) | N41: https://www.societe.com/societe/ami-facade-910405794.html
...

Sheet Base
A1: SIREN | B1: Nom | C1: Classement | D1: Spécialité | E1: Alerte | F1: Méthode de vérification | G1: Preuve | H1: Source | I1: Code NAF | J1: Libellé NAF | K1: Tranche effectif (code INSEE) | L1: Effectif (salariés) | M1: Commune | N1: Code postal | O1: Département | P1: Procédure collective (BODACC) | Q1: Date procédure | R1: Qualifications RGE valides | S1: Activité déclarée au greffe (BODACC) | T1: Date de création
A2: 851694190 | B2: CAVIEUX FACADES | C2: Confirmé | D2: Façadier (ravalement, enduits, ITE, bardage) | F2: automatique (RGE ADEME / site web) | G2: RGE isolation des murs par l'extérieur (ADEME) ; site web : enduit, facade, ite, ravalement ; mot-clé dans le nom/enseigne ; NAF 43.99C BTP cohérent | H2: https://data.ademe.fr/datasets/liste-des-entreprises-rge-2 | I2: 43.99C | J2: Travaux de maçonnerie générale et gros œuvre de bâtiment | K2: 03 | L2: 6 à 9 | M2: SAINT-ANDRE-DE-CORCY | N2: 01390 | O2: 01 | R2: Isolation des murs par l'extérieur | S2: ravalement de façades, isolation et peintures extérieures / ravalement de façades et isolation par l'extérieur | T2: 2019-06-07
A3: 419678396 | B3: E.R.T.B.I. (ERTBI FACADES ENVIRONNEMENT) | C3: Confirmé | D3: Multi-activité (façade parmi d'autres métiers) | F3: recherche web (agent IA) | G3: échafaudage + travaux de façade extérieure, plâtrerie (multi-activité) | H3: https://lyon-entreprises.com/Annuaire/ERTBI-FACADES-ENVIRONNEMENT-20427/coordonnees-caluire-et-cuire.html | I3: 43.99B | J3: Travaux de montage de structures métalliques | K3: 03 | L3: 6 à 9 | M3: CHARNOZ-SUR-AIN | N3: 01800 | O3: 01 | T3: 1998-08-01
A4: 538058041 | B4: REIS BARDAGE | C4: Confirmé | D4: Couvreur / étancheur faisant du bardage | F4: BODACC (activité déclarée au greffe) | G4: activité déclarée : Travaux de couverture et de bardage. | H4: https://www.bodacc.fr/ (SIREN 538058041) | I4: 43.91B | J4: Travaux de couverture par éléments | K4: 03 | L4: 6 à 9 | M4: LA BOISSE | N4: 01120 | O4: 01 | S4: Travaux de couverture et de bardage. | T4: 2011-11-15
A5: 915208334 | B5: TECHNO BARDAGE | C5: Confirmé | D5: Couvreur / étancheur faisant du bardage | F5: BODACC (activité déclarée au greffe) | G5: activité déclarée : couverture et bardage | H5: https://www.bodacc.fr/ (SIREN 915208334) | I5: 43.91B | J5: Travaux de couverture par éléments | K5: 03 | L5: 6 à 9 | M5: MONTLUEL | N5: 01120 | O5: 01 | S5: couverture et bardage | T5: 2022-07-15
A6: 828285437 | B6: CFP TECHNI-FACADES | C6: Confirmé | D6: Façadier (ravalement, enduits, ITE, bardage) | F6: automatique (RGE ADEME / site web) | G6: RGE isolation des murs par l'extérieur (ADEME) ; mot-clé dans le nom/enseigne ; NAF 43.99C BTP cohérent | H6: https://data.ademe.fr/datasets/liste-des-entreprises-rge-2 | I6: 43.99C | J6: Travaux de maçonnerie générale et gros œuvre de bâtiment | K6: 03 | L6: 6 à 9 | M6: BRUGHEAS | N6: 03700 | O6: 03 | R6: Isolation des murs par l'extérieur | S6: Ravalement de façades, isolation extérieure, projection d'enduit à la chaux, peinture, petite maçonnerie. | T6: 2017-03-08
A7: 978246767 | B7: DK FACADE ITE PEINTURE | C7: Confirmé | D7: Façadier (ravalement, enduits, ITE, bardage) | F7: recherche web (agent IA) | G7: ravalement, ITE, peinture | H7: https://servicesartisans.fr/services/facadier/manosque/dk-facade-ite-peinture-978246767 | I7: 43.99C | J7: Travaux de maçonnerie générale et gros œuvre de bâtiment | K7: 03 | L7: 6 à 9 | M7: MANOSQUE | N7: 04100 | O7: 04 | T7: 2023-08-01
A8: 814514162 | B8: K 2 (CONCEPT FACADES) | C8: Confirmé | D8: Façadier (ravalement, enduits, ITE, bardage) | F8: recherche web (agent IA) | G8: enseigne CONCEPT FACADES : ravalement, peinture, ITE ; 20-49 salariés | H8: https://annuaire-entreprises.data.gouv.fr/entreprise/814514162 | I8: 43.99C | J8: Travaux de maçonnerie générale et gros œuvre de bâtiment | K8: 12 | L8: 20 à 49 | M8: BIOT | N8: 06410 | O8: 06 | S8: Ravalement façades peinture isolation extérieure. | T8: 2015-09-11
A9: 847633633 | B9: SASU BATI PROJECT FACADES | C9: Confirmé | D9: Façadier (ravalement, enduits, ITE, bardage) | F9: recherche web (agent IA) | G9: ravalement / nettoyage de façades (+ négoce carrelage) | H9: https://www.pagesjaunes.fr/pros/60786535 | I9: 43.33Z | J9: Travaux de revêtement des sols et des murs | K9: 03 | L9: 6 à 9 | M9: ANTIBES | N9: 06600 | O9: 06 | T9: 2018-12-17
